Workbook
Name Slicer_Quarter: #N/A
Name Slicer_Month: #N/A
Name Slicer_Segment: #N/A
Name Slicer_Year: #N/A

Sheet data
A1: Segment | B1: Country | C1: Product_Name | D1: Customer_ID | E1: Product_ID | F1: Customer_Name | G1: Discount Band | H1: Date | I1: Month | J1: Quarter | K1: Year | L1: Units Sold | M1: Manufacturing Price | N1: Sale Price | O1: Gross Sales | P1: Discounts | Q1: Net Sales | R1: Sales ('000) | S1: COGS | T1: Profit
A2: Enterprise | B2: USA | C2: X-Terrain | D2: CUST_ID_001 | E2: PROD_ID_001 | F2: James Smith | G2: None | H2: 44096 | I2: Sep | J2: Q3 | K2: 2020 | L2: 414 | M2: 6.00 | N2: 188.00 | O2: 77.832 | P2: - | Q2: 77.832 | R2: 43.13 | S2: 2.484 | T2: 75.348
A3: Midmarket | B3: Canada | C3: City Cruiser | D3: CUST_ID_002 | E3: PROD_ID_002 | F3: Emma Johnson | G3: None | H3: 43841 | I3: Jan | J3: Q1 | K3: 2020 | L3: 659 | M3: 12.00 | N3: 23.00 | O3: 15.157 | P3: - | Q3: 15.157 | R3: 45505 | S3: 7.908 | T3: 7.249
A4: Small Business | B4: England | C4: City Cruiser | D4: CUST_ID_003 | E4: PROD_ID_002 | F4: Noah Williams | G4: None | H4: 44223 | I4: Jan | J4: Q1 | K4: 2021 | L4: 946 | M4: 12.00 | N4: 450.00 | O4: 425.7 | P4: - | Q4: 425.7 | R4: 236.40 | S4: 11.352 | T4: 414.348
A5: Government | B5: France | C5: City Cruiser | D5: CUST_ID_004 | E5: PROD_ID_002 | F5: Olivia Brown | G5: None | H5: 44044 | I5: Aug | J5: Q3 | K5: 2020 | L5: 2.07 | M5: 12.00 | N5: 525.00 | O5: 1,086,750 | P5: - | Q5: 1,086,750 | R5: 603.75 | S5: 24.84 | T5: 1,061,910
A6: Channel Partners | B6: Germany | C6: City Cruiser | D6: CUST_ID_005 | E6: PROD_ID_002 | F6: Liam Jones | G6: None | H6: 44385 | I6: Jul | J6: Q3 | K6: 2021 | L6: 1.094 | M6: 12.00 | N6: 18.00 | O6: 19.692 | P6: - | Q6: 19.692 | R6: 34608 | S6: 13.128 | T6: 6.564
A7: Midmarket | B7: Italy | C7: City Cruiser | D7: CUST_ID_006 | E7: PROD_ID_002 | F7: Ava Davis | G7: None | H7: 44467 | I7: Sep | J7: Q3 | K7: 2021 | L7: 2.582 | M7: 12.00 | N7: 23.00 | O7: 59.386 | P7: - | Q7: 59.386 | R7: 32.28 | S7: 30.984 | T7: 28.402
A8: Enterprise | B8: India | C8: Speedster | D8: CUST_ID_007 | E8: PROD_ID_003 | F8: Ethan Miller | G8: None | H8: 44100 | I8: Sep | J8: Q3 | K8: 2020 | L8: 414 | M8: 148.00 | N8: 188.00 | O8: 77.832 | P8: - | Q8: 77.832 | R8: 43.13 | S8: 61.272 | T8: 16.56
A9: Government | B9: Japan | C9: Trail Master | D9: CUST_ID_008 | E9: PROD_ID_004 | F9: Isabella Wilson | G9: None | H9: 43872 | I9: Feb | J9: Q1 | K9: 2020 | L9: 1.832 | M9: 308.00 | N9: 525.00 | O9: 961.8 | P9: - | Q9: 961.8 | R9: 534.45 | S9: 564.256 | T9: 397.544
A10: Enterprise | B10: USA | C10: Road Racer | D10: CUST_ID_009 | E10: PROD_ID_005 | F10: Mason Taylor | G10: Low | H10: 44208 | I10: Jan | J10: Q1 | K10: 2021 | L10: 396 | M10: 4.00 | N10: 188.00 | O10: 74.448 | P10: 744 | Q10: 73.704 | R10: 40.84 | S10: 1.584 | T10: 72.12
A11: Channel Partners | B11: Canada | C11: Road Racer | D11: CUST_ID_010 | E11: PROD_ID_005 | F11: Sophia Anderson | G11: Low | H11: 44292 | I11: Apr | J11: Q2 | K11: 2021 | L11: 919 | M11: 4.00 | N11: 18.00 | O11: 16.542 | P11: 165 | Q11: 16.377 | R11: 45939 | S11: 3.676 | T11: 12.701
A12: Small Business | B12: England | C12: Road Racer | D12: CUST_ID_011 | E12: PROD_ID_005 | F12: Benjamin Martinez | G12: Low | H12: 44154 | I12: Nov | J12: Q4 | K12: 2020 | L12: 593 | M12: 4.00 | N12: 450.00 | O12: 266.85 | P12: 2.669 | Q12: 264.182 | R12: 146.72 | S12: 2.372 | T12: 261.81
A13: Small Business | B13: France | C13: X-Terrain | D13: CUST_ID_012 | E13: PROD_ID_001 | F13: Mia Thomas | G13: Low | H13: 44185 | I13: Dec | J13: Q4 | K13: 2020 | L13: 2.998 | M13: 6.00 | N13: 450.00 | O13: 1,349,100 | P13: 13.491 | Q13: 1,335,609 | R13: 741.91 | S13: 17.988 | T13: 1,317,621
A14: Enterprise | B14: Germany | C14: X-Terrain | D14: CUST_ID_013 | E14: PROD_ID_001 | F14: Logan Jackson | G14: Low | H14: 43888 | I14: Feb | J14: Q1 | K14: 2020 | L14: 796 | M14: 6.00 | N14: 188.00 | O14: 149.648 | P14: 1.496 | Q14: 148.152 | R14: 82.05 | S14: 4.776 | T14: 143.376
A15: Channel Partners | B15: Italy | C15: City Cruiser | D15: CUST_ID_014 | E15: PROD_ID_002 | F15: Charlotte White | G15: Low | H15: 44387 | I15: Jul | J15: Q3 | K15: 2021 | L15: 919 | M15: 12.00 | N15: 18.00 | O15: 16.542 | P15: 165 | Q15: 16.377 | R15: 45939 | S15: 11.028 | T15: 5.349
A16: Enterprise | B16: India | C16: Speedster | D16: CUST_ID_015 | E16: PROD_ID_003 | F16: Samuel Taylor | G16: Low | H16: 44284 | I16: Mar | J16: Q1 | K16: 2021 | L16: 796 | M16: 148.00 | N16: 188.00 | O16: 149.648 | P16: 1.496 | Q16: 148.152 | R16: 82.05 | S16: 117.808 | T16: 30.344
A17: Government | B17: Japan | C17: Speedster | D17: CUST_ID_016 | E17: PROD_ID_003 | F17: Harper Davis | G17: Low | H17: 44488 | I17: Oct | J17: Q4 | K17: 2021 | L17: 2.51 | M17: 148.00 | N17: 11.00 | O17: 27.61 | P17: 276 | Q17: 27.334 | R17: 14.50 | S17: 371.48 | T17: -344.146
A18: Small Business | B18: USA | C18: Trail Master | D18: CUST_ID_017 | E18: PROD_ID_004 | F18: Henry Anderson | G18: Low | H18: 44408 | I18: Jul | J18: Q3 | K18: 2021 | L18: 593 | M18: 308.00 | N18: 450.00 | O18: 266.85 | P18: 2.669 | Q18: 264.182 | R18: 146.72 | S18: 182.644 | T18: 81.538
A19: Channel Partners | B19: Canada | C19: Yellow Edition | D19: CUST_ID_018 | E19: PROD_ID_006 | F19: Amelia Garcia | G19: Low | H19: 44284 | I19: Mar | J19: Q1 | K19: 2021 | L19: 2.387 | M19: 320.00 | N19: 18.00 | O19: 42.966 | P19: 430 | Q19: 42.536 | R19: 23.63 | S19: 763.84 | T19: -721.304
A20: Midmarket | B20: England | C20: Yellow Edition | D20: CUST_ID_019 | E20: PROD_ID_006 | F20: Jackson Martinez | G20: Low | H20: 44404 | I20: Jul | J20: Q3 | K20: 2021 | L20: 385 | M20: 320.00 | N20: 23.00 | O20: 8.855 | P20: 89 | Q20: 8.766 | R20: 28216 | S20: 123.2 | T20: -114.434
A21: Small Business | B21: France | C21: Road Racer | D21: CUST_ID_020 | E21: PROD_ID_005 | F21: Abigail Robinson | G21: Low | H21: 44073 | I21: Aug | J21: Q3 | K21: 2020 | L21: 257 | M21: 4.00 | N21: 450.00 | O21: 115.65 | P21: 2.313 | Q21: 113.337 | R21: 62.92 | S21: 1.028 | T21: 112.309
A22: Government | B22: Germany | C22: Road Racer | D22: CUST_ID_021 | E22: PROD_ID_005 | F22: Aiden Lewis | G22: Low | H22: 44119 | I22: Oct | J22: Q4 | K22: 2020 | L22: 2.574 | M22: 4.00 | N22: 11.00 | O22: 28.314 | P22: 566 | Q22: 27.748 | R22: 14.71 | S22: 10.296 | T22: 17.452
A23: Enterprise | B23: Italy | C23: X-Terrain | D23: CUST_ID_022 | E23: PROD_ID_001 | F23: Emily Clark | G23: Low | H23: 44499 | I23: Oct | J23: Q4 | K23: 2021 | L23: 1.992 | M23: 6.00 | N23: 188.00 | O23: 374.496 | P23: 7.49 | Q23: 367.006 | R23: 203.35 | S23: 11.952 | T23: 355.054
A24: Enterprise | B24: India | C24: City Cruiser | D24: CUST_ID_023 | E24: PROD_ID_002 | F24: Sebastian Lee | G24: Low | H24: 44175 | I24: Dec | J24: Q4 | K24: 2020 | L24: 971 | M24: 12.00 | N24: 188.00 | O24: 182.548 | P24: 3.651 | Q24: 178.897 | R24: 99.10 | S24: 11.652 | T24: 167.245
A25: Enterprise | B25: Japan | C25: City Cruiser | D25: CUST_ID_024 | E25: PROD_ID_002 | F25: Elizabeth Green | G25: Low | H25: 43974 | I25: May | J25: Q2 | K25: 2020 | L25: 2.574 | M25: 12.00 | N25: 188.00 | O25: 483.912 | P25: 9.678 | Q25: 474.234 | R25: 262.76 | S25: 30.888 | T25: 443.346
A26: Channel Partners | B26: USA | C26: City Cruiser | D26: CUST_ID_025 | E26: PROD_ID_002 | F26: Alexander Perez | G26: Low | H26: 43879 | I26: Feb | J26: Q1 | K26: 2020 | L26: 2.142 | M26: 12.00 | N26: 18.00 | O26: 38.556 | P26: 771 | Q26: 37.785 | R26: 20.99 | S26: 25.704 | T26: 12.081
A27: Midmarket | B27: Canada | C27: City Cruiser | D27: CUST_ID_026 | E27: PROD_ID_002 | F27: Avery Turner | G27: Low | H27: 43858 | I27: Jan | J27: Q1 | K27: 2020 | L27: 2.31 | M27: 12.00 | N27: 23.00 | O27: 53.13 | P27: 1.063 | Q27: 52.067 | R27: 28.30 | S27: 27.72 | T27: 24.347
A28: Government | B28: England | C28: City Cruiser | D28: CUST_ID_027 | E28: PROD_ID_002 | F28: Michael Hill | G28: Low | H28: 44551 | I28: Dec | J28: Q4 | K28: 2021 | L28: 2.416 | M28: 12.00 | N28: 11.00 | O28: 26.576 | P28: 532 | Q28: 26.044 | R28: 13.81 | S28: 28.992 | T28: -2.948
A29: Government | B29: France | C29: Speedster | D29: CUST_ID_028 | E29: PROD_ID_003 | F29: Sofia Phillips | G29: Low | H29: 44209 | I29: Jan | J29: Q1 | K29: 2021 | L29: 3.559 | M29: 148.00 | N29: 525.00 | O29: 1,868,475 | P29: 37.37 | Q29: 1,831,106 | R29: 1,017.34 | S29: 526.732 | T29: 1,304,374
A30: Enterprise | B30: Germany | C30: Speedster | D30: CUST_ID_029 | E30: PROD_ID_003 | F30: Elijah Martin | G30: Low | H30: 44508 | I30: Nov | J30: Q4 | K30: 2021 | L30: 971 | M30: 148.00 | N30: 188.00 | O30: 182.548 | P30: 3.651 | Q30: 178.897 | R30: 99.10 | S30: 143.708 | T30: 35.189
A31: Enterprise | B31: Italy | C31: Speedster | D31: CUST_ID_030 | E31: PROD_ID_003 | F31: Sophia Turner | G31: Low | H31: 43849 | I31: Jan | J31: Q1 | K31: 2020 | L31: 2.574 | M31: 148.00 | N31: 188.00 | O31: 483.912 | P31: 9.678 | Q31: 474.234 | R31: 262.76 | S31: 380.952 | T31: 93.282
A32: Government | B32: India | C32: Speedster | D32: CUST_ID_031 | E32: PROD_ID_003 | F32: Benjamin Lee | G32: Low | H32: 44042 | I32: Jul | J32: Q3 | K32: 2020 | L32: 653 | M32: 148.00 | N32: 30.00 | O32: 19.59 | P32: 392 | Q32: 19.198 | R32: 24381 | S32: 96.644 | T32: -77.446
A33: Small Business | B33: Japan | C33: Trail Master | D33: CUST_ID_032 | E33: PROD_ID_004 | F33: Mia White | G33: Low | H33: 43882 | I33: Feb | J33: Q1 | K33: 2020 | L33: 257 | M33: 308.00 | N33: 450.00 | O33: 115.65 | P33: 2.313 | Q33: 113.337 | R33: 62.92 | S33: 79.156 | T33: 34.181
A34: Government | B34: USA | C34: Trail Master | D34: CUST_ID_033 | E34: PROD_ID_004 | F34: Logan Garcia | G34: Low | H34: 44224 | I34: Jan | J34: Q1 | K34: 2021 | L34: 319 | M34: 308.00 | N34: 525.00 | O34: 167.475 | P34: 3.35 | Q34: 164.126 | R34: 91.24 | S34: 98.252 | T34: 65.874
A35: Government | B35: Canada | C35: Trail Master | D35: CUST_ID_034 | E35: PROD_ID_004 | F35: Charlotte Davis | G35: Low | H35: 44208 | I35: Jan | J35: Q1 | K35: 2021 | L35: 2.328 | M35: 308.00 | N35: 525.00 | O35: 1,222,200 | P35: 24.444 | Q35: 1,197,756 | R35: 665.42 | S35: 717.024 | T35: 480.732
A36: Government | B36: England | C36: Yellow Edition | D36: CUST_ID_035 | E36: PROD_ID_006 | F36: Samuel Johnson | G36: Low | H36: 44378 | I36: Jul | J36: Q3 | K36: 2021 | L36: 3.559 | M36: 320.00 | N36: 525.00 | O36: 1,868,475 | P36: 37.37 | Q36: 1,831,106 | R36: 1,017.34 | S36: 1,138,880 | T36: 692.226
A37: Channel Partners | B37: France | C37: Road Racer | D37: CUST_ID_036 | E37: PROD_ID_005 | F37: Harper Anderson | G37: Low | H37: 44541 | I37: Dec | J37: Q4 | K37: 2021 | L37: 1.09 | M37: 4.00 | N37: 18.00 | O37: 19.62 | P37: 589 | Q37: 19.031 | R37: 21094 | S37: 4.36 | T37: 14.671
A38: Government | B38: Germany | C38: X-Terrain | D38: CUST_ID_037 | E38: PROD_ID_001 | F38: Henry Martinez | G38: Low | H38: 43967 | I38: May | J38: Q2 | K38: 2020 | L38: 2.156 | M38: 6.00 | N38: 525.00 | O38: 1,131,900 | P38: 33.957 | Q38: 1,097,943 | R38: 610.08 | S38: 12.936 | T38: 1,085,007
A39: Midmarket | B39: Italy | C39: City Cruiser | D39: CUST_ID_038 | E39: PROD_ID_002 | F39: Amelia Wilson | G39: Low | H39: 44318 | I39: May | J39: Q2 | K39: 2021 | L39: 2.334 | M39: 12.00 | N39: 23.00 | O39: 53.682 | P39: 1.61 | Q39: 52.072 | R39: 28.30 | S39: 28.008 | T39: 24.064
A40: Midmarket | B40: India | C40: Trail Master | D40: CUST_ID_039 | E40: PROD_ID_004 | F40: Jackson Turner | G40: Low | H40: 44288 | I40: Apr | J40: Q2 | K40: 2021 | L40: 2.334 | M40: 308.00 | N40: 23.00 | O40: 53.682 | P40: 1.61 | Q40: 52.072 | R40: 28.30 | S40: 718.872 | T40: -666.8
...

Sheet Analysis
A2: Segment
A3: Row Labels | B3: Sum of Net Sales | D3: Row Labels | E3: Sum of Net Sales | G3: Product name | J3: Month | V3: Row Labels | W3: Sum of Net Sales
A4: Channel Partners | B4: 3241.054 | D4: Canada | E4: 13485.657 | J4: Row Labels | K4: Sum of Net Sales | L4: Month | M4: Actual | N4: Budget | O4: Actual | P4: Budget | S4: Row Labels | T4: Sum of Net Sales | V4: Abigail Clark | W4: 42.412
A5: Enterprise | B5: 35394.76 | D5: England | E5: 14649.515 | J5: Jan | K5: 12734.705 | L5: =J5 -> Jan | M5: =GETPIVOTDATA("Net Sales",$K$5,"Month",L5) -> 12734.705 | N5: =Sheet4!A2 -> £18,300,908 | S5: 2020 | T5: 59230.128 | V5: Abigail Garcia | W5: 3173.568
A6: Government | B6: 42685.77 | D6: France | E6: 10781.288 | J6: Feb | K6: 11408.102 | L6: =J6 -> Feb | M6: =GETPIVOTDATA("Net Sales",$K$5,"Month",L6) -> 11408.102 | N6: =Sheet4!A3 -> £23,544,303 | S6: 2021 | T6: 58713.748 | V6: Abigail Lewis | W6: 2362.966
A7: Midmarket | B7: 4382.609 | D7: Germany | E7: 18164.176 | J7: Mar | K7: 5961.393 | L7: =J7 -> Mar | M7: =GETPIVOTDATA("Net Sales",$K$5,"Month",L7) -> 5961.393 | N7: =Sheet4!A4 -> £21,303,974 | S7: Grand Total | T7: 117943.88 | V7: Abigail Martin | W7: 1314.275
A8: Small Business | B8: 32239.683 | D8: India | E8: 15520.059 | J8: Apr | K8: 10336.968 | L8: =J8 -> Apr | M8: =GETPIVOTDATA("Net Sales",$K$5,"Month",L8) -> 10336.968 | N8: =Sheet4!A5 -> £10,611,142 | V8: Abigail Phillips | W8: 1448.544
A9: Grand Total | B9: 117943.88 | D9: Italy | E9: 15582.742 | J9: May | K9: 10306.451 | L9: =J9 -> May | M9: =GETPIVOTDATA("Net Sales",$K$5,"Month",L9) -> 10306.451 | N9: =Sheet4!A6 -> £14,661,451 | V9: Abigail Robinson | W9: 474.323
B10: =GETPIVOTDATA("Net Sales",$A$3) -> 117943.88 | D10: Japan | E10: 16333.316 | J10: Jun | K10: 10935.368 | L10: =J10 -> Jun | M10: =GETPIVOTDATA("Net Sales",$K$5,"Month",L10) -> 10935.368 | N10: =Sheet4!A7 -> £22,614,104 | V10: Aiden Anderson | W10: 77.87
D11: USA | E11: 13427.123 | J11: Jul | K11: 11102.754 | L11: =J11 -> Jul | M11: =GETPIVOTDATA("Net Sales",$K$5,"Month",L11) -> 11102.754 | N11: =Sheet4!A8 -> £18,334,867 | V11: Aiden Clark | W11: 1192.497
D12: Grand Total | E12: 117943.88 | J12: Aug | K12: 8161.552 | L12: =J12 -> Aug | M12: =GETPIVOTDATA("Net Sales",$K$5,"Month",L12) -> 8161.552 | N12: =Sheet4!A9 -> £20,514,113 | V12: Aiden Garcia | W12: 871.167
J13: Sep | K13: 6882.857 | L13: =J13 -> Sep | M13: =GETPIVOTDATA("Net Sales",$K$5,"Month",L13) -> 6882.857 | N13: =Sheet4!A10 -> £20,199,830 | V13: Aiden Hill | W13: 167.14
J14: Oct | K14: 10989.934 | L14: =J14 -> Oct | M14: =GETPIVOTDATA("Net Sales",$K$5,"Month",L14) -> 10989.934 | N14: =Sheet4!A11 -> £12,194,030 | V14: Aiden Lewis | W14: 1173.382
J15: Nov | K15: 8667.366 | L15: =J15 -> Nov | M15: =GETPIVOTDATA("Net Sales",$K$5,"Month",L15) -> 8667.366 | N15: =Sheet4!A12 -> £12,337,191 | V15: Aiden Martin | W15: 2054.159
J16: Dec | K16: 10456.426 | L16: =J16 -> Dec | M16: =GETPIVOTDATA("Net Sales",$K$5,"Month",L16) -> 10456.426 | N16: =Sheet4!A13 -> £15,522,499 | O16: =M16 -> 10456.426 | P16: =N16 -> £15,522,499 | V16: Aiden Perez | W16: 96.394
J17: Grand Total | K17: 117943.88 | N17: =Sheet4!A14 -> £210,138,410 | V17: Alexander Hill | W17: 56.037
V18: Alexander Perez | W18: 195.497
V19: Amelia Garcia | W19: 222.535
V20: Amelia Hill | W20: 509.904
A21: PROFIT | V21: Amelia Martin | W21: 2025.813
V22: Amelia Perez | W22: 410.782
A23: Row Labels | B23: Sum of Profit | D23: Row Labels | E23: Sum of Profit | I23: Row Labels | J23: Sum of Net Sales | V23: Amelia Phillips | W23: 972.834
A24: Channel Partners | B24: -17220.726 | D24: Canada | E24: 1703.041 | F24: =GETPIVOTDATA("Profit",$D$23,"Country",D24) -> 1703.041 | G24: =SUM(F24)/SUM($F$24:$F$31) -> 0.08169547 | I24: City Cruiser | J24: 32667.544 | K24: =GETPIVOTDATA("Net Sales",$I$23,"Product_Name",I24) -> 32667.544 | L24: =SUM(K24)/SUM($K$24:$K$29) -> 0.27697533 | V24: Amelia Wilson | W24: 207.353
A25: Enterprise | B25: 12877.01 | D25: England | E25: 2621.577 | F25: =GETPIVOTDATA("Profit",$D$23,"Country",D25) -> 2621.577 | G25: =SUM(F25)/SUM($F$24:$F$31) -> 0.12575796 | I25: X-Terrain | J25: 17550.051 | K25: =GETPIVOTDATA("Net Sales",$I$23,"Product_Name",I25) -> 17550.051 | L25: =SUM(K25)/SUM($K$24:$K$29) -> 0.14880002 | V25: Ava Davis | W25: 364.587
A26: Government | B26: 5933.185 | D26: France | E26: 2983.784 | F26: =GETPIVOTDATA("Profit",$D$23,"Country",D26) -> 2983.784 | G26: =SUM(F26)/SUM($F$24:$F$31) -> 0.14313316 | I26: Road Racer | J26: 17276.45 | K26: =GETPIVOTDATA("Net Sales",$I$23,"Product_Name",I26) -> 17276.45 | L26: =SUM(K26)/SUM($K$24:$K$29) -> 0.14648026 | V26: Avery Anderson | W26: 175.226
A27: Midmarket | B27: -13869.991 | D27: Germany | E27: 7633.574 | F27: =GETPIVOTDATA("Profit",$D$23,"Country",D27) -> 7633.574 | G27: =SUM(F27)/SUM($F$24:$F$31) -> 0.3661852 | I27: Speedster | J27: 17588.964 | K27: =GETPIVOTDATA("Net Sales",$I$23,"Product_Name",I27) -> 17588.964 | L27: =SUM(K27)/SUM($K$24:$K$29) -> 0.14912995 | V27: Avery Turner | W27: 407.634
A28: Small Business | B28: 33126.733 | D28: India | E28: -3228.023 | F28: =GETPIVOTDATA("Profit",$D$23,"Country",D28) -> -3228.023 | G28: =SUM(F28)/SUM($F$24:$F$31) -> -0.15484939 | I28: Trail Master | J28: 18000.232 | K28: =GETPIVOTDATA("Net Sales",$I$23,"Product_Name",I28) -> 18000.232 | L28: =SUM(K28)/SUM($K$24:$K$29) -> 0.15261693 | V28: Benjamin Garcia | W28: 2248.431
A29: Grand Total | B29: 20846.211 | D29: Italy | E29: 10867.723 | F29: =GETPIVOTDATA("Profit",$D$23,"Country",D29) -> 10867.723 | G29: =SUM(F29)/SUM($F$24:$F$31) -> 0.52132846 | I29: Yellow Edition | J29: 14860.635 | K29: =GETPIVOTDATA("Net Sales",$I$23,"Product_Name",I29) -> 14860.635 | L29: =SUM(K29)/SUM($K$24:$K$29) -> 0.12599751 | V29: Benjamin Hill | W29: 315.468
D30: Japan | E30: 3746.768 | F30: =GETPIVOTDATA("Profit",$D$23,"Country",D30) -> 3746.768 | G30: =SUM(F30)/SUM($F$24:$F$31) -> 0.17973377 | I30: Grand Total | J30: 117943.88 | V30: Benjamin Lee | W30: 1094.198
D31: USA | E31: -5482.233 | F31: =GETPIVOTDATA("Profit",$D$23,"Country",D31) -> -5482.233 | G31: =SUM(F31)/SUM($F$24:$F$31) -> -0.26298463 | V31: Benjamin Martin | W31: 2059.331
D32: Grand Total | E32: 20846.211 | F32: =GETPIVOTDATA("Profit",$D$23) -> 20846.211 | V32: Benjamin Martinez | W32: 636.089
V33: Benjamin Phillips | W33: 3775.86
V34: Charlotte Anderson | W34: 716.46
V35: Charlotte Davis | W35: 1039.715
V36: Charlotte Garcia | W36: 2073.587
A37: UNIT SOLD | V37: Charlotte Hill | W37: 468.174
V38: Charlotte Martin | W38: 2182.142
A39: Row Labels | B39: Sum of Units Sold | D39: Row Labels | E39: Sum of Units Sold | V39: Charlotte White | W39: 78.229
A40: Channel Partners | B40: 12575.121 | D40: Canada | E40: 9657.981 | V40: Elijah Martin | W40: 789.581
A41: Enterprise | B41: 18571.872 | D41: England | E41: 15507.397 | V41: Elijah Perez | W41: 1199.299
...

Sheet Sheet4
A1: Budget
A2: £18,300,908
A3: £23,544,303
A4: £21,303,974
A5: £10,611,142
A6: £14,661,451
A7: £22,614,104
A8: £18,334,867
A9: £20,514,113
A10: £20,199,830
A11: £12,194,030
A12: £12,337,191
... A19: Target
A20: Revenue | B20: £210,138,410
A21: Profit | B21: £60,429,310
A22: Profit Margin | B22: 28.76%
A23: Unit Sold | B23: 1,420,956

Sheet DASHBOARD
